Workbook

Sheet Sheet7
A1: ISO code 3 | B1: ISO Alpha 3 | C1: Countries | D1: ISO Alpha 2 | E1: Leading commodities exported | F1: Commodity dependence | G1: Leading destination markets
A2: 4 | B2: AFG | C2: Afghanistan | D2: AF | E2: 58.9 | F2: 95.2 | G2: =VLOOKUP(B2, Sheet18!$B:$E, 4, FALSE) -> 86.7
A3: 8 | B3: ALB | C3: Albania | D3: AL | E3: 11.9 | F3: 32.1 | G3: =VLOOKUP(B3, Sheet18!$B:$E, 4, FALSE) -> 87.9
A4: 12 | B4: DZA | C4: Algeria | D4: DZ | E4: 82.8 | F4: 96 | G4: =VLOOKUP(B4, Sheet18!$B:$E, 4, FALSE) -> 74.8
A5: 20 | B5: AND | C5: Andorra | D5: AD | E5: 4.6 | F5: 8.1 | G5: =VLOOKUP(B5, Sheet18!$B:$E, 4, FALSE) -> 89.9
A6: 24 | B6: AGO | C6: Angola | D6: AO | E6: 90.1 | F6: 96.1 | G6: =VLOOKUP(B6, Sheet18!$B:$E, 4, FALSE) -> 78.2
A7: 28 | B7: ATG | C7: Antigua and Barbuda | D7: AG | E7: 34.7 | F7: 40 | G7: =VLOOKUP(B7, Sheet18!$B:$E, 4, FALSE) -> 75.3
A8: 32 | B8: ARG | C8: Argentina | D8: AR | E8: 38.6 | F8: 80.9 | G8: =VLOOKUP(B8, Sheet18!$B:$E, 4, FALSE) -> 48.3
A9: 51 | B9: ARM | C9: Armenia | D9: AM | E9: 45.6 | F9: 74.7 | G9: =VLOOKUP(B9, Sheet18!$B:$E, 4, FALSE) -> 87.3
A10: 36 | B10: AUS | C10: Australia | D10: AU | E10: 55.7 | F10: 91.6 | G10: =VLOOKUP(B10, Sheet18!$B:$E, 4, FALSE) -> 68.6
A11: 40 | B11: AUT | C11: Austria | D11: AT | E11: 4.9 | F11: 18.2 | G11: =VLOOKUP(B11, Sheet18!$B:$E, 4, FALSE) -> 88.5
A12: 31 | B12: AZE | C12: Azerbaijan | D12: AZ | E12: 89.5 | F12: 95.7 | G12: =VLOOKUP(B12, Sheet18!$B:$E, 4, FALSE) -> 88.7
A13: 44 | B13: BHS | C13: Bahamas (the) | D13: BS | E13: 50.3 | F13: 53.7 | G13: =VLOOKUP(B13, Sheet18!$B:$E, 4, FALSE) -> 85
... A74: 332 | B74: HTI | C74: Haiti | D74: HT | E74: 3.2 | F74: 6.7 | G74: =VLOOKUP(B74, Sheet18!$B:$E, 4, FALSE) -> 57.8
A75: 336 | B75: VAT | C75: Holy see (the) | D75: VA | G75: =VLOOKUP(B75, Sheet18!$B:$E, 4, FALSE)
A76: 340 | B76: HND | C76: Honduras | D76: HN | E76: 30 | F76: 53.5 | G76: =VLOOKUP(B76, Sheet18!$B:$E, 4, FALSE) -> 83.6
A77: 348 | B77: HUN | C77: Hungary | D77: HU | E77: 3.4 | F77: 14.1 | G77: =VLOOKUP(B77, Sheet18!$B:$E, 4, FALSE) -> 89.2
A78: 352 | B78: ISL | C78: Iceland | D78: IS | E78: 75.8 | F78: 84.5 | G78: =VLOOKUP(B78, Sheet18!$B:$E, 4, FALSE) -> 90.7
A79: 356 | B79: IND | C79: India | D79: IN | E79: 26.1 | F79: 40.5 | G79: =VLOOKUP(B79, Sheet18!$B:$E, 4, FALSE) -> 35.9
A80: 360 | B80: IDN | C80: Indonesia | D80: ID | E80: 26.9 | F80: 55.5 | G80: =VLOOKUP(B80, Sheet18!$B:$E, 4, FALSE) -> 60.9
A81: 364 | B81: IRN | C81: Iran (Islamic Republic of) | D81: IR | E81: 22.3 | F81: 51.4 | G81: =VLOOKUP(B81, Sheet18!$B:$E, 4, FALSE) -> 68
A82: 368 | B82: IRQ | C82: Iraq | D82: IQ | E82: 97.5 | F82: 99.5 | G82: =VLOOKUP(B82, Sheet18!$B:$E, 4, FALSE) -> 73.8
A83: 372 | B83: IRL | C83: Ireland | D83: IE | E83: 3.2 | F83: 9.7 | G83: =VLOOKUP(B83, Sheet18!$B:$E, 4, FALSE) -> 81.8
A84: 376 | B84: ISR | C84: Israel | D84: IL | E84: 15.6 | F84: 21 | G84: =VLOOKUP(B84, Sheet18!$B:$E, 4, FALSE) -> 72.3
A85: 380 | B85: ITA | C85: Italy | D85: IT | E85: 6.1 | F85: 18.3 | G85: =VLOOKUP(B85, Sheet18!$B:$E, 4, FALSE) -> 72.6
A86: 388 | B86: JAM | C86: Jamaica | D86: JM | E86: 69.2 | F86: 94.8 | G86: =VLOOKUP(B86, Sheet18!$B:$E, 4, FALSE) -> 73.4
A87: 392 | B87: JPN | C87: Japan | D87: JP | E87: 5.2 | F87: 9.8 | G87: =VLOOKUP(B87, Sheet18!$B:$E, 4, FALSE) -> 54.6
... A115: 498 | B115: MDA | C115: Republic of Moldova (the) | D115: MD | E115: 24.4 | F115: 55.9 | G115: =VLOOKUP(B115, Sheet18!$B:$E, 4, FALSE) -> 87.7
A116: 492 | B116: MCO | C116: Monaco | D116: MC | G116: =VLOOKUP(B116, Sheet18!$B:$E, 4, FALSE)
A117: 496 | B117: MNG | C117: Mongolia | D117: MN | E117: 76 | F117: 98.8 | G117: =VLOOKUP(B117, Sheet18!$B:$E, 4, FALSE) -> 98.6
A118: 499 | B118: MNE | C118: Montenegro | D118: ME | E118: 45.5 | F118: 71.8 | G118: =VLOOKUP(B118, Sheet18!$B:$E, 4, FALSE) -> 94.1
A119: 504 | B119: MAR | C119: Morocco | D119: MA | E119: 16.6 | F119: 26.3 | G119: =VLOOKUP(B119, Sheet18!$B:$E, 4, FALSE) -> 70.1
A120: 508 | B120: MOZ | C120: Mozambique | D120: MZ | E120: 49.7 | F120: 96.5 | G120: =VLOOKUP(B120, Sheet18!$B:$E, 4, FALSE) -> 52.6
A121: 104 | B121: MMR | C121: Myanmar | D121: MM | E121: 31.7 | F121: 55.8 | G121: =VLOOKUP(B121, Sheet18!$B:$E, 4, FALSE) -> 90
A122: 516 | B122: NAM | C122: Namibia | D122: NA | E122: 45.9 | F122: 82.5 | G122: =VLOOKUP(B122, Sheet18!$B:$E, 4, FALSE) -> 73.8
A123: 520 | B123: NRU | C123: Nauru | D123: NR | E123: 94.8 | F123: 94.9 | G123: =VLOOKUP(B123, Sheet18!$B:$E, 4, FALSE) -> 92.5
A124: 524 | B124: NPL | C124: Nepal | D124: NP | E124: 29.3 | F124: 48.1 | G124: =VLOOKUP(B124, Sheet18!$B:$E, 4, FALSE) -> 96.1
A125: 528 | B125: NLD | C125: Netherlands (Kingdom of the) | D125: NL | E125: 15.4 | F125: 37.8 | G125: =VLOOKUP(B125, Sheet18!$B:$E, 4, FALSE) -> 83.9
A126: 554 | B126: NZL | C126: New Zealand | D126: NZ | E126: 32.9 | F126: 81 | G126: =VLOOKUP(B126, Sheet18!$B:$E, 4, FALSE) -> 54.9
A127: 558 | B127: NIC | C127: Nicaragua | D127: NI | E127: 31.6 | F127: 57.9 | G127: =VLOOKUP(B127, Sheet18!$B:$E, 4, FALSE) -> 79.7
...

Sheet Sheet17
B1: Commodity dependence (%)
A2: Afghanistan | B2: 0.952
A3: Albania | B3: 0.321
A4: Algeria | B4: 0.96
A5: Andorra | B5: 0.081
A6: Angola | B6: 0.961
A7: Antigua and Barbuda | B7: 0.4
A8: Argentina | B8: 0.809
A9: Armenia | B9: 0.747
A10: Australia | B10: 0.916
A11: Austria | B11: 0.182
A12: Azerbaijan | B12: 0.957
A13: Bahamas (the) | B13: 0.537
... A74: Haiti | B74: 0.067
A75: Holy see (the) | B75: #DIV/0!
A76: Honduras | B76: 0.535
A77: Hungary | B77: 0.141
A78: Iceland | B78: 0.845
A79: India | B79: 0.405
A80: Indonesia | B80: 0.555
A81: Iran (Islamic Republic of) | B81: 0.514
A82: Iraq | B82: 0.995
A83: Ireland | B83: 0.097
A84: Israel | B84: 0.21
A85: Italy | B85: 0.183
A86: Jamaica | B86: 0.948
A87: Japan | B87: 0.098
... A115: Republic of Moldova (the) | B115: 0.559
A116: Monaco | B116: #DIV/0!
A117: Mongolia | B117: 0.988
A118: Montenegro | B118: 0.718
A119: Morocco | B119: 0.263
A120: Mozambique | B120: 0.965
A121: Myanmar | B121: 0.558
A122: Namibia | B122: 0.825
A123: Nauru | B123: 0.949
A124: Nepal | B124: 0.481
A125: Netherlands (Kingdom of the) | B125: 0.378
A126: New Zealand | B126: 0.81
A127: Nicaragua | B127: 0.579
...

Sheet Sheet18
A1: ISO code 3 | B1: ISO Alpha 3 | C1: ISO Alpha 2 | D1: Countries | E1: Leading destination markets (%)
A2: 4 | B2: AFG | C2: AF | D2: Afghanistan | E2: 86.7
A3: 8 | B3: ALB | C3: AL | D3: Albania | E3: 87.9
A4: 12 | B4: DZA | C4: DZ | D4: Algeria | E4: 74.8
A5: 20 | B5: AND | C5: AD | D5: Andorra | E5: 89.9
A6: 24 | B6: AGO | C6: AO | D6: Angola | E6: 78.2
A7: 28 | B7: ATG | C7: AG | D7: Antigua and Barbuda | E7: 75.3
A8: 32 | B8: ARG | C8: AR | D8: Argentina | E8: 48.3
A9: 51 | B9: ARM | C9: AM | D9: Armenia | E9: 87.3
A10: 36 | B10: AUS | C10: AU | D10: Australia | E10: 68.6
A11: 40 | B11: AUT | C11: AT | D11: Austria | E11: 88.5
A12: 31 | B12: AZE | C12: AZ | D12: Azerbaijan | E12: 88.7
A13: 44 | B13: BHS | C13: BS | D13: Bahamas (the) | E13: 85
... A74: 332 | B74: HTI | C74: HT | D74: Haiti | E74: 57.8
A75: 336 | B75: VAT | C75: VA | D75: Holy see (the)
A76: 340 | B76: HND | C76: HN | D76: Honduras | E76: 83.6
A77: 348 | B77: HUN | C77: HU | D77: Hungary | E77: 89.2
A78: 352 | B78: ISL | C78: IS | D78: Iceland | E78: 90.7
A79: 356 | B79: IND | C79: IN | D79: India | E79: 35.9
A80: 360 | B80: IDN | C80: ID | D80: Indonesia | E80: 60.9
A81: 364 | B81: IRN | C81: IR | D81: Iran (Islamic Republic of) | E81: 68
A82: 368 | B82: IRQ | C82: IQ | D82: Iraq | E82: 73.8
A83: 372 | B83: IRL | C83: IE | D83: Ireland | E83: 81.8
A84: 376 | B84: ISR | C84: IL | D84: Israel | E84: 72.3
A85: 380 | B85: ITA | C85: IT | D85: Italy | E85: 72.6
A86: 388 | B86: JAM | C86: JM | D86: Jamaica | E86: 73.4
A87: 392 | B87: JPN | C87: JP | D87: Japan | E87: 54.6
... A115: 498 | B115: MDA | C115: MD | D115: Republic of Moldova (the) | E115: 87.7
A116: 492 | B116: MCO | C116: MC | D116: Monaco
A117: 496 | B117: MNG | C117: MN | D117: Mongolia | E117: 98.6
A118: 499 | B118: MNE | C118: ME | D118: Montenegro | E118: 94.1
A119: 504 | B119: MAR | C119: MA | D119: Morocco | E119: 70.1
A120: 508 | B120: MOZ | C120: MZ | D120: Mozambique | E120: 52.6
A121: 104 | B121: MMR | C121: MM | D121: Myanmar | E121: 90
A122: 516 | B122: NAM | C122: NA | D122: Namibia | E122: 73.8
A123: 520 | B123: NRU | C123: NR | D123: Nauru | E123: 92.5
A124: 524 | B124: NPL | C124: NP | D124: Nepal | E124: 96.1
A125: 528 | B125: NLD | C125: NL | D125: Netherlands (Kingdom of the) | E125: 83.9
A126: 554 | B126: NZL | C126: NZ | D126: New Zealand | E126: 54.9
A127: 558 | B127: NIC | C127: NI | D127: Nicaragua | E127: 79.7
...

Sheet Sheet16
A1: number | B1: indicator | D1: indicator_full | E1: indicator_key | G1: desire | H1: decimals | I1: indicator_short | J1: format | K1: group | L1: round_digits | M1: max_label | N1: max_overall_label | O1: min | P1: max | Q1: min_overall | R1: max_overall
A2: 1.1 | B2: gov_debt_to_gdp_perc | C2: =VLOOKUP(B2,B$26:B$43,1,false) -> gov_debt_to_gdp_perc | D2: Public debt as a share of GDP | E2: gov_debt_to_gdp_perc | G2: Lower is better | H2: 1 | I2: as a share of GDP | J2: percent | K2: Public debt | L2: 2 | M2: 3.1 | N2: 6.1 | O2: 0.00525 | P2: 3.08747 | Q2: 2e-05 | R2: 6.00109
A3: 1.2 | B3: gov_debt_usd_billions | C3: =VLOOKUP(B3,B$26:B$43,1,false) -> gov_debt_usd_billions | D3: Public debt in US$ billions | E3: gov_debt_usd_billions | G3: Lower is better | H3: 0 | I3: in US$ billions | J3: dollar | K3: Public debt | L3: 2 | M3: 75000 | N3: 75000 | O3: 0.00208974 | P3: 74930.685 | Q3: 2.32e-05 | R3: 74930.685
A4: 1.3 | B4: gov_debt_usd_per_capita | C4: =VLOOKUP(B4,B$26:B$43,1,false) -> gov_debt_usd_per_capita | D4: Public debt in US$ per capita | E4: gov_debt_usd_per_capita | G4: Neutral | H4: 0 | I4: in US$ per capita | J4: dollar | K4: Public debt | L4: 2 | M4: 180000 | N4: 180000 | O4: 35.76866 | P4: 170180.64 | Q4: 0.020658949 | R4: 170180.64
A5: 2.1 | B5: external_ppg_perc_gdp | C5: =VLOOKUP(B5,B$26:B$43,1,false) -> external_ppg_perc_gdp | D5: External public debt as a share of GDP | E5: external_ppg_perc_gdp | G5: Lower is better | H5: 1 | I5: as a share of GDP | J5: percent | K5: External public debt | L5: 2 | M5: 1.2 | N5: 4 | O5: 0.00077635392 | P5: 1.1496043 | Q5: 8.6206897e-06 | R5: 3.9327552
A6: 2.2 | B6: external_ppg_usd_billions | C6: =VLOOKUP(B6,B$26:B$43,1,false) -> external_ppg_usd_billions | D6: External public debt in US$ billions | E6: external_ppg_usd_billions | G6: Lower is better | H6: 0 | I6: in US$ billions | J6: dollar | K6: External public debt | L6: 1 | M6: 600 | N6: 600 | O6: 0.12934676 | P6: 504.11253 | Q6: 1e-05 | R6: 554.29225
A7: 2.3 | B7: external_ppg_per_capita | C7: =VLOOKUP(B7,B$26:B$43,1,false) -> external_ppg_per_capita | D7: External public debt in US$ per capita | E7: external_ppg_per_capita | G7: Neutral | H7: 0 | I7: in US$ per capita | J7: dollar | K7: External public debt | L7: 2 | M7: 11000 | N7: 11000 | O7: 3.7532405 | P7: 10187.488 | Q7: 0.0089047195 | R7: 10187.488
A8: 3.1 | B8: multilateral_share_external_ppg | C8: =VLOOKUP(B8,B$26:B$43,1,false) -> multilateral_share_external_ppg | D8: Multilateral creditors as a share of external public debt | E8: multilateral_share_external_ppg | G8: Neutral | H8: 1 | I8: multilateral | J8: percent | K8: External public debt by creditor | L8: 1 | M8: 1 | N8: 1 | O8: 0.03887657 | P8: 0.93534616 | Q8: 0.0012835581 | R8: 1
A9: 3.2 | B9: bilateral_share_external_ppg | C9: =VLOOKUP(B9,B$26:B$43,1,false) -> bilateral_share_external_ppg | D9: Bilateral creditors as a share of external public debt | E9: bilateral_share_external_ppg | G9: Neutral | H9: 1 | I9: bilateral | J9: percent | K9: External public debt by creditor | L9: 1 | M9: 0.7 | N9: 1 | O9: 0.0095138939 | P9: 0.69973798 | Q9: 0 | R9: 0.96516533
A10: 3.3 | B10: private_share_external_ppg | C10: =VLOOKUP(B10,B$26:B$43,1,false) -> private_share_external_ppg | D10: Private creditors as a share of external public debt | E10: private_share_external_ppg | G10: Neutral | H10: 1 | I10: private | J10: percent | K10: External public debt by creditor | L10: 1 | M10: 1 | N10: 1 | O10: 0 | P10: 0.93039106 | Q10: 0 | R10: 0.98946373
A11: 4.1 | B11: gov_net_interest_perc_gdp | C11: =VLOOKUP(B11,B$26:B$43,1,false) -> gov_net_interest_perc_gdp | D11: Public debt interest payments as a share of GDP | E11: gov_net_interest_perc_gdp | G11: Lower is better | H11: 1 | I11: as a share of GDP | J11: percent | K11: Public debt interest payments | L11: 2 | M11: 0.1 | N11: 0.18 | O11: -0.30606549 | P11: 0.098196931 | Q11: -0.30606549 | R11: 0.17266474
A12: 4.2 | B12: gov_net_interest_perc_revenues | C12: =VLOOKUP(B12,B$26:B$43,1,false) -> gov_net_interest_perc_revenues | D12: Public debt interest payments as a share of revenues | E12: gov_net_interest_perc_revenues | G12: Lower is better | H12: 1 | I12: as a share of net revenue | J12: percent | K12: Public debt interest payments | L12: 1 | M12: 0.7 | N12: 2 | O12: -0.39008774 | P12: 0.60935377 | Q12: -0.39484118 | R12: -0.39484118
A13: 4.3 | B13: gov_net_interest_per_capita | C13: =VLOOKUP(B13,B$26:B$43,1,false) -> gov_net_interest_per_capita | D13: Public debt interest payments in US$ per capita | E13: gov_net_interest_per_capita | G13: Lower is better | H13: 0 | I13: in US$ per capita | J13: dollar | K13: Public debt interest payments | L13: 2 | M13: 3300 | N13: 3300 | O13: -9449.8918 | P13: 3288.3501 | Q13: -9449.8918 | R13: 3288.3501
... A19: 5.6 | B19: gov_spending_perc_net_interest | C19: =VLOOKUP(B19,B$26:B$43,1,false) -> gov_spending_perc_net_interest | D19: Ratio of public interest payments to investment expenditure | E19: gov_investment_perc_net_interest | G19: Lower is better | H19: 1 | I19: ratio of net interest to investment | J19: number | K19: Debt burden relative to development spending | L19: 1 | M19: 0.5 | N19: 2 | O19: -0.61088478 | P19: 0.43315805 | Q19: -0.61088478 | R19: 1.2113137
A24: WOrks
A25: number | B25: indicator | D25: indicator_full | E25: indicator_key | G25: desire | H25: decimals | I25: indicator_short | J25: format | K25: group | L25: round_digits | M25: max_label | N25: max_overall_label | O25: min | P25: max | Q25: min_overall | R25: max_overall
A26: 1.1 | B26: gov_debt_to_gdp_perc | D26: Public debt as a share of GDP | E26: gov_debt_to_gdp_perc | F26: =VLOOKUP(E26,E$2:E$19,1,false) -> gov_debt_to_gdp_perc | G26: Lower is better | H26: 1 | I26: as a share of GDP | J26: percent | K26: Public debt | L26: 2 | M26: 2.8 | N26: 6.1 | O26: 0 | P26: 2.71979 | Q26: 0 | R26: 6.00117
A27: 1.2 | B27: gov_debt_usd_billions | D27: Public debt in US$ billions | E27: gov_debt_usd_billions | F27: =VLOOKUP(E27,E$2:E$19,1,false) -> gov_debt_usd_billions | G27: Lower is better | H27: 0 | I27: in US$ billions | J27: dollar | K27: Public debt | L27: 2 | M27: 36000 | N27: 36000 | O27: 0 | P27: 35251.273 | Q27: 0 | R27: 35251.273
A28: 1.3 | B28: gov_debt_usd_per_capita | D28: Public debt in US$ per capita | E28: gov_debt_usd_per_capita | F28: =VLOOKUP(E28,E$2:E$19,1,false) -> gov_debt_usd_per_capita | G28: Neutral | H28: 0 | I28: in US$ per capita | J28: dollar | K28: Public debt | L28: 2 | M28: 160000 | N28: 160000 | O28: 0 | P28: 158040.43 | Q28: 0 | R28: 158040.43
A29: 2.1 | B29: external_ppg_perc_gdp | D29: External public debt as a share of GDP | E29: external_ppg_perc_gdp | F29: =VLOOKUP(E29,E$2:E$19,1,false) -> external_ppg_perc_gdp | G29: Lower is better | H29: 1 | I29: as a share of GDP | J29: percent | K29: External public debt | L29: 2 | M29: 1.5 | N29: 4 | O29: 0.0010411096 | P29: 1.4213335 | Q29: 8.62e-06 | R29: 3.9327552
A30: 2.2 | B30: external_ppg_usd_billions | D30: External public debt in US$ billions | E30: external_ppg_usd_billions | F30: =VLOOKUP(E30,E$2:E$19,1,false) -> external_ppg_usd_billions | G30: Lower is better | H30: 0 | I30: in US$ billions | J30: dollar | K30: External public debt | L30: 1 | M30: 500 | N30: 500 | O30: 0.15136267 | P30: 467.99599 | Q30: 1e-05 | R30: 475.16725
A31: 2.3 | B31: external_ppg_per_capita | D31: External public debt in US$ per capita | E31: external_ppg_per_capita | F31: =VLOOKUP(E31,E$2:E$19,1,false) -> external_ppg_per_capita | G31: Neutral | H31: 0 | I31: in US$ per capita | J31: dollar | K31: External public debt | L31: 2 | M31: 8700 | N31: 8700 | O31: 4.525909 | P31: 8609.6011 | Q31: 0.0088105727 | R31: 8609.6011
A32: 3.1 | B32: multilateral_share_external_ppg | D32: Multilateral creditors as a share of external public debt | E32: multilateral_share_external_ppg | F32: =VLOOKUP(E32,E$2:E$19,1,false) -> multilateral_share_external_ppg | G32: Neutral | H32: 1 | I32: multilateral | J32: percent | K32: External public debt by creditor | L32: 1 | M32: 1 | N32: 1 | O32: 0.034783496 | P32: 0.98046411 | Q32: 0.0012836207 | R32: 1
A33: 3.2 | B33: bilateral_share_external_ppg | D33: Bilateral creditors as a share of external public debt | E33: bilateral_share_external_ppg | F33: =VLOOKUP(E33,E$2:E$19,1,false) -> bilateral_share_external_ppg | G33: Neutral | H33: 1 | I33: bilateral | J33: percent | K33: External public debt by creditor | L33: 1 | M33: 1 | N33: 1 | O33: 0.0083490497 | P33: 0.94843956 | Q33: 0 | R33: 0.96516533
A34: 3.3 | B34: private_share_external_ppg | D34: Private creditors as a share of external public debt | E34: private_share_external_ppg | F34: =VLOOKUP(E34,E$2:E$19,1,false) -> private_share_external_ppg | G34: Neutral | H34: 1 | I34: private | J34: percent | K34: External public debt by creditor | L34: 1 | M34: 1 | N34: 1 | O34: 0 | P34: 0.93536437 | Q34: 0 | R34: 0.98946373
A35: 4.1 | B35: gov_net_interest_perc_gdp | D35: Public debt interest payments as a share of GDP | E35: gov_net_interest_perc_gdp | F35: =VLOOKUP(E35,E$2:E$19,1,false) -> gov_net_interest_perc_gdp | G35: Lower is better | H35: 1 | I35: as a share of GDP | J35: percent | K35: Public debt interest payments | L35: 2 | M35: 0.09 | N35: 0.18 | O35: -0.22668202 | P35: 0.088223798 | Q35: -0.22668202 | R35: 0.17714556
A36: 4.2 | B36: gov_net_interest_perc_revenues | D36: Public debt interest payments as a share of revenues | E36: gov_net_interest_perc_revenues | F36: =VLOOKUP(E36,E$2:E$19,1,false) -> gov_net_interest_perc_revenues | G36: Lower is better | H36: 1 | I36: as a share of net revenue | J36: percent | K36: Public debt interest payments | L36: 1 | M36: 0.7 | N36: 2 | O36: -0.31304842 | P36: 0.61256708 | Q36: -0.37048894 | R36: 1.1172161
A37: 4.3 | B37: gov_net_interest_per_capita | D37: Public debt interest payments in US$ per capita | E37: gov_net_interest_per_capita | F37: =VLOOKUP(E37,E$2:E$19,1,false) -> gov_net_interest_per_capita | G37: Lower is better | H37: 0 | I37: in US$ per capita | J37: dollar | K37: Public debt interest payments | L37: 2 | M37: 3200 | N37: 3200 | O37: -7171.6909 | P37: 3173.1922 | Q37: -7171.6909 | R37: 3173.1922
... A43: 5.6 | B43: health_spending_perc_net_interest | D43: Ratio of public interest payments to health expenditure | E43: health_spending_perc_net_interest | F43: =VLOOKUP(E43,E$2:E$19,1,false) -> health_spending_perc_net_interest | G43: Lower is better | H43: 1 | I43: ratio of net interest to health | J43: number | K43: Debt burden relative to development spending | L43: 1 | M43: 9 | N43: 9 | O43: -3.9144927 | P43: 8.8211354 | Q43: -4.5211927 | R43: 8.8211354

Sheet Sheet15
A1: Date | B1: All goods | C1: All services | D1: Marine and coastal tourism | E1: Maritime transport and related services: passengers | F1: Maritime transport and related services: freight | G1: Port services, related infrastructure services and logistical services | H1: Marine research and development and related licenses | I1: Other services
A2: Ocean trade, 2025 | B2: 1.02719 | D2: 0.784812 | E2: 0.015560936 | F2: 0.487102 | G2: 0.144289 | H2: 0.005729643 | I2: 0.021290579
A3: Total trade, 2025 | B3: 26.3 | C3: 9.65
A4: Ocean trade, 2020 | B4: 0.711 | D4: 0.219198 | E4: 0.006248236 | F4: 0.303349 | G4: 0.101791 | H4: 0.004018001 | I4: 0.010266237
A5: Total trade, 2020 | B5: 17.6 | C5: 5.33

Sheet Sheet14
A1: date | B1: crude | C1: gasoline
A2: 45292 | B2: 71.7 | C2: 755.7
A3: 45293 | B3: 70.4 | C3: 767.6
A4: 45294 | B4: 72.2 | C4: 756.6
A5: 45295 | B5: 71.2 | C5: 771.5
A6: 45296 | B6: 73.1 | C6: 764.8
A7: 45299 | B7: 70.2 | C7: 745.3
A8: 45300 | B8: 72.1 | C8: 751.3
A9: 45301 | B9: 71.7 | C9: 755.2
A10: 45302 | B10: 72.8 | C10: 763.3
A11: 45303 | B11: 73.1 | C11: 776
A12: 45306 | B12: 72.8 | C12: 772
A13: 45307 | B13: 73 | C13: 776.3
... A176: 45534 | B176: 77 | C176: 756.3
A177: 02-Sept-24 | B177: 75.3 | C177: 745
A178: 03-Sept-24 | B178: 72.8 | C178: 717.5
A179: 04-Sept-24 | B179: 71.6 | C179: 704.3
A180: 05-Sept-24 | B180: 71.5 | C180: 696.2
A181: 06-Sept-24 | B181: 72.7 | C181: 686.8
A182: 09-Sept-24 | B182: 69.9 | C182: 695.5
A183: 10-Sept-24 | B183: 67.6 | C183: 689
A184: 11-Sept-24 | B184: 68.4 | C184: 687
A185: 12-Sept-24 | B185: 70.8 | C185: 698.6
A186: 13-Sept-24 | B186: 70.5 | C186: 700
A187: 16-Sept-24 | B187: 71.3 | C187: 703.8
A188: 17-Sept-24 | B188: 72.2 | C188: 714.9
... A197: 30-Sept-24 | B197: 69.9 | C197: 701.6
A198: 45566 | B198: 72 | C198: 696.7
A199: 45567 | B199: 72.1 | C199: 712.2
A200: 45568 | B200: 75.3 | C200: 726.4
A201: 45569 | B201: 76.3 | C201: 746.7
A202: 45572 | B202: 78.9 | C202: 758.6
A203: 45573 | B203: 75.2 | C203: 750.2
A204: 45574 | B204: 74.6 | C204: 739.2
A205: 45575 | B205: 76.9 | C205: 753.3
A206: 45576 | B206: 77.2 | C206: 765
A207: 45579 | B207: 75.9 | C207: 762.3
A208: 45580 | B208: 71.7 | C208: 724.7
A209: 45581 | B209: 71.7 | C209: 727.5
... A436: 45898 | B436: 66.5 | C436: 757.7
...

Sheet Sheet8
A1: date | B1: UNCTAD_region | C1: gdp_per_capita | D1: wealth_99_perc | I1: date | J1: UNCTAD_region | K1: gdp_per_capita | L1: wealth_99_perc | O1: date | P1: UNCTAD_region | Q1: gdp_per_capita | R1: wealth_99_perc
A2: 2000 | B2: Eastern Europe | C2: 100 | D2: 76.72 | I2: 2000 | J2: Eastern Europe | K2: 100 | L2: 76.72 | O2: 2000 | P2: Southern Europe | Q2: 100 | R2: 77.28
A3: 2001 | B3: Eastern Europe | C3: 106.69667 | D3: 76.78 | I3: 2001 | J3: Eastern Europe | K3: 106.69667 | L3: 76.78 | O3: 2001 | P3: Southern Europe | Q3: 102.17784 | R3: 77.3
A4: 2002 | B4: Eastern Europe | C4: 114.86523 | D4: 76.75 | I4: 2002 | J4: Eastern Europe | K4: 114.86523 | L4: 76.75 | O4: 2002 | P4: Southern Europe | Q4: 104.31153 | R4: 77.27
A5: 2003 | B5: Eastern Europe | C5: 118.40534 | D5: 76.81 | I5: 2003 | J5: Eastern Europe | K5: 118.40534 | L5: 76.81 | O5: 2003 | P5: Southern Europe | Q5: 107.57943 | R5: 77.27
A6: 2004 | B6: Eastern Europe | C6: 131.49992 | D6: 76.74 | I6: 2004 | J6: Eastern Europe | K6: 131.49992 | L6: 76.74 | O6: 2004 | P6: Southern Europe | Q6: 108.19705 | R6: 77.3
A7: 2005 | B7: Eastern Europe | C7: 138.49112 | D7: 76.78 | I7: 2005 | J7: Eastern Europe | K7: 138.49112 | L7: 76.78 | O7: 2005 | P7: Southern Europe | Q7: 111.4468 | R7: 77.29
A8: 2006 | B8: Eastern Europe | C8: 150.49923 | D8: 76.66 | I8: 2006 | J8: Eastern Europe | K8: 150.49923 | L8: 76.66 | O8: 2006 | P8: Southern Europe | Q8: 114.67842 | R8: 77.28
A9: 2007 | B9: Eastern Europe | C9: 163.78779 | D9: 76.455 | I9: 2007 | J9: Eastern Europe | K9: 163.78779 | L9: 76.455 | O9: 2007 | P9: Southern Europe | Q9: 118.46933 | R9: 77.31
A10: 2008 | B10: Eastern Europe | C10: 182.04064 | D10: 76.265 | I10: 2008 | J10: Eastern Europe | K10: 182.04064 | L10: 76.265 | O10: 2008 | P10: Southern Europe | Q10: 122.09252 | R10: 77.27
A11: 2009 | B11: Eastern Europe | C11: 173.43687 | D11: 76.535 | I11: 2009 | J11: Eastern Europe | K11: 173.43687 | L11: 76.535 | O11: 2009 | P11: Southern Europe | Q11: 118.168 | R11: 77.28
A12: 2010 | B12: Eastern Europe | C12: 167.65561 | D12: 76.225 | I12: 2010 | J12: Eastern Europe | K12: 167.65561 | L12: 76.225 | O12: 2010 | P12: Southern Europe | Q12: 120.16613 | R12: 77.29
A13: 2011 | B13: Eastern Europe | C13: 176.05655 | D13: 76.215 | I13: 2011 | J13: Eastern Europe | K13: 176.05655 | L13: 76.215 | O13: 2011 | P13: Southern Europe | Q13: 118.2809 | R13: 77.2
... A21: 2019 | B21: Eastern Europe | C21: 219.90737 | D21: 75.45 | I21: 2019 | J21: Eastern Europe | K21: 219.90737 | L21: 75.45 | O21: 2019 | P21: Southern Europe | Q21: 119.69599 | R21: 76.85
A22: 2000 | B22: Southern Europe | C22: 100 | D22: 77.28
A23: 2001 | B23: Southern Europe | C23: 102.17784 | D23: 77.3
A24: 2002 | B24: Southern Europe | C24: 104.31153 | D24: 77.27
A25: 2003 | B25: Southern Europe | C25: 107.57943 | D25: 77.27 | I25: date | J25: Eastern Europe | K25: Southern Europe | N25: date | O25: Eastern Europe | P25: Southern Europe
A26: 2004 | B26: Southern Europe | C26: 108.19705 | D26: 77.3 | I26: 2000 | J26: 100 | K26: 100 | N26: 2000 | O26: 76.72 | P26: 77.28
A27: 2005 | B27: Southern Europe | C27: 111.4468 | D27: 77.29 | I27: 2001 | J27: 106.69667 | K27: 102.17784 | N27: 2001 | O27: 76.78 | P27: 77.3
A28: 2006 | B28: Southern Europe | C28: 114.67842 | D28: 77.28 | I28: 2002 | J28: 114.86523 | K28: 104.31153 | N28: 2002 | O28: 76.75 | P28: 77.27
A29: 2007 | B29: Southern Europe | C29: 118.46933 | D29: 77.31 | I29: 2003 | J29: 118.40534 | K29: 107.57943 | N29: 2003 | O29: 76.81 | P29: 77.27
A30: 2008 | B30: Southern Europe | C30: 122.09252 | D30: 77.27 | I30: 2004 | J30: 131.49992 | K30: 108.19705 | N30: 2004 | O30: 76.74 | P30: 77.3
A31: 2009 | B31: Southern Europe | C31: 118.168 | D31: 77.28 | I31: 2005 | J31: 138.49112 | K31: 111.4468 | N31: 2005 | O31: 76.78 | P31: 77.29
A32: 2010 | B32: Southern Europe | C32: 120.16613 | D32: 77.29 | I32: 2006 | J32: 150.49923 | K32: 114.67842 | N32: 2006 | O32: 76.66 | P32: 77.28
A33: 2011 | B33: Southern Europe | C33: 118.2809 | D33: 77.2 | I33: 2007 | J33: 163.78779 | K33: 118.46933 | N33: 2007 | O33: 76.455 | P33: 77.31
A34: 2012 | B34: Southern Europe | C34: 109.82571 | D34: 77.19 | I34: 2008 | J34: 182.04064 | K34: 122.09252 | N34: 2008 | O34: 76.265 | P34: 77.27
A35: 2013 | B35: Southern Europe | C35: 107.63747 | D35: 76.96 | I35: 2009 | J35: 173.43687 | K35: 118.168 | N35: 2009 | O35: 76.535 | P35: 77.28
A36: 2014 | B36: Southern Europe | C36: 109.21528 | D36: 76.91 | I36: 2010 | J36: 167.65561 | K36: 120.16613 | N36: 2010 | O36: 76.225 | P36: 77.29
A37: 2015 | B37: Southern Europe | C37: 109.68625 | D37: 76.86 | I37: 2011 | J37: 176.05655 | K37: 118.2809 | N37: 2011 | O37: 76.215 | P37: 77.2
... A41: 2019 | B41: Southern Europe | C41: 119.69599 | D41: 76.85 | I41: 2015 | J41: 196.46325 | K41: 109.68625 | N41: 2015 | O41: 75.72 | P41: 76.86
I42: 2016 | J42: 203.24457 | K42: 110.10838 | N42: 2016 | O42: 75.87 | P42: 76.8
I43: 2017 | J43: 209.53251 | K43: 111.95161 | N43: 2017 | O43: 75.455 | P43: 76.77
I44: 2018 | J44: 215.25927 | K44: 114.4951 | N44: 2018 | O44: 75.4 | P44: 76.82
I45: 2019 | J45: 219.90737 | K45: 119.69599 | N45: 2019 | O45: 75.45 | P45: 76.85

Sheet Sheet9
A1: group | B1: UNCTAD_region | C1: value | D1: label
A2: 2014 | B2: Northern Africa | C2: 100 | D2: GDP per Capita
A3: 2014 | B3: Northern Africa | C3: 13.926 | D3: Share of people who say most people can be trusted
A4: 2022 | B4: Northern Africa | C4: 110.45941 | D4: GDP per Capita
A5: 2022 | B5: Northern Africa | C5: 11.469106 | D5: Share of people who say most people can be trusted
A6: 2014 | B6: Western Asia | C6: 100 | D6: GDP per Capita
A7: 2014 | B7: Western Asia | C7: 11.62453 | D7: Share of people who say most people can be trusted
A8: 2022 | B8: Western Asia | C8: 125.91902 | D8: GDP per Capita
A9: 2022 | B9: Western Asia | C9: 13.99586 | D9: Share of people who say most people can be trusted
A13: Date | B13: Group | C13: Value | G13: Date | H13: Group | I13: Value
A14: 2014 | B14: Northern Africa | C14: 100 | D14: GDP per Capita | G14: 2014 | H14: Northern Africa | I14: 13.926 | J14: Share of people who say most people can be trusted
A15: 2022 | B15: Northern Africa | C15: 110.45941 | D15: GDP per Capita | G15: 2022 | H15: Northern Africa | I15: 11.469106 | J15: Share of people who say most people can be trusted
A16: 2014 | B16: Western Asia | C16: 100 | D16: GDP per Capita | G16: 2014 | H16: Western Asia | I16: 11.62453 | J16: Share of people who say most people can be trusted
A17: 2022 | B17: Western Asia | C17: 125.91902 | D17: GDP per Capita | G17: 2022 | H17: Western Asia | I17: 13.99586 | J17: Share of people who say most people can be trusted
A21: Group | B21: 2014 | C21: 2022
A22: Northern Africa | B22: 13.926 | C22: 11.469106
A23: Western Asia | B23: 11.62453 | C23: 13.99586

Sheet Sheet10
A1: iso3 | B1: Satisfaction with public services | C1: Country | D1: Satisfaction with public services | E1: Gross domestic product (GDP) per capita
A2: CYP | B2: 95.464 | C2: =VLOOKUP(A2, Sheet11!A:B,2,false) -> Cyprus | D2: 95.464 | E2: 19738.54
A3: BLR | B3: 94.88889 | C3: =VLOOKUP(A3, Sheet11!A:B,2,false) -> Belarus | D3: 94.88889 | E3: 6238.306
A4: LTU | B4: 89.07121 | C4: =VLOOKUP(A4, Sheet11!A:B,2,false) -> Lithuania | D4: 89.07121 | E4: 17150.16
A5: MEX | B5: 84.40457 | C5: =VLOOKUP(A5, Sheet11!A:B,2,false) -> Mexico | D5: 84.40457 | E5: 10032.34
A6: ZAF | B6: 80.76667 | C6: =VLOOKUP(A6, Sheet11!A:B,2,false) -> South Africa | D6: 80.76667 | E6: 5906.275
A7: FIN | B7: 78.375 | C7: =VLOOKUP(A7, Sheet11!A:B,2,false) -> Finland | D7: 78.375 | E7: 44929.83
A8: TUN | B8: 77.44444 | C8: =VLOOKUP(A8, Sheet11!A:B,2,false) -> Tunisia | D8: 77.44444 | E8: 3998.618
A9: NLD | B9: 76.025 | C9: =VLOOKUP(A9, Sheet11!A:B,2,false) -> Netherlands (the) | D9: 76.025 | E9: 48862.03
A10: CHE | B10: 71.6 | C10: =VLOOKUP(A10, Sheet11!A:B,2,false) -> Switzerland | D10: 71.6 | E10: 87131.35
A11: EST | B11: 71.3 | C11: =VLOOKUP(A11, Sheet11!A:B,2,false) -> Estonia | D11: 71.3 | E11: 19849.76
A12: LUX | B12: 70.925 | C12: =VLOOKUP(A12, Sheet11!A:B,2,false) -> Luxembourg | D12: 70.925 | E12: 106852.1
A13: IRL | B13: 70.3 | C13: =VLOOKUP(A13, Sheet11!A:B,2,false) -> Ireland | D13: 70.3 | E13: 80823.91
... A34: GMB | B34: 38.61111 | C34: =VLOOKUP(A34, Sheet11!A:B,2,false) -> Gambia (the) | D34: 38.61111 | E34: 676.995

Sheet Sheet12
A1: iso3 | B1: Share reporting discrimination or harassment | C1: GDP per capita (log scale) | D1: Country | E1: Satisfaction with public services | F1: GDP per capita
A2: AGO | B2: 34.2 | C2: 3151.3417 | D2: =VLOOKUP(A2,Sheet11!A:B,2,false) -> Angola | E2: 34.2 | F2: 3151.3417
A3: AUT | B3: 28.333333 | C3: 45296.547 | D3: =VLOOKUP(A3,Sheet11!A:B,2,false) -> Austria | E3: 28.333333 | F3: 45296.547
A4: BDI | B4: 5.7522222 | C4: 263.51682 | D4: =VLOOKUP(A4,Sheet11!A:B,2,false) -> Burundi | E4: 5.7522222 | F4: 263.51682
A5: BEL | B5: 38 | C5: 42522.117 | D5: =VLOOKUP(A5,Sheet11!A:B,2,false) -> Belgium | E5: 38 | F5: 42522.117
A6: BEN | B6: 4.80625 | C6: 1122.8551 | D6: =VLOOKUP(A6,Sheet11!A:B,2,false) -> Benin | E6: 4.80625 | F6: 1122.8551
A7: BFA | B7: 12.866667 | C7: 699.343 | D7: =VLOOKUP(A7,Sheet11!A:B,2,false) -> Burkina Faso | E7: 12.866667 | F7: 699.343
A8: BGR | B8: 1.855 | C8: 8511.7258 | D8: =VLOOKUP(A8,Sheet11!A:B,2,false) -> Bulgaria | E8: 1.855 | F8: 8511.7258
A9: BLR | B9: 1.19375 | C9: 6235.9977 | D9: =VLOOKUP(A9,Sheet11!A:B,2,false) -> Belarus | E9: 1.19375 | F9: 6235.9977
A10: BLZ | B10: 19.1 | C10: 5926.1219 | D10: =VLOOKUP(A10,Sheet11!A:B,2,false) -> Belize | E10: 19.1 | F10: 5926.1219
A11: BOL | B11: 3.2693498 | C11: 3052.7131 | D11: =VLOOKUP(A11,Sheet11!A:B,2,false) -> Bolivia (Plurinational State of) | E11: 3.2693498 | F11: 3052.7131
A12: BWA | B12: 20.666667 | C12: 6741.2223 | D12: =VLOOKUP(A12,Sheet11!A:B,2,false) -> Botswana | E12: 20.666667 | F12: 6741.2223
A13: CAF | B13: 11.81875 | C13: 387.2839 | D13: =VLOOKUP(A13,Sheet11!A:B,2,false) -> Central African Republic (the) | E13: 11.81875 | F13: 387.2839
... A24: CYP | B24: 18.333333 | C24: 19400.358 | D24: =VLOOKUP(A24,Sheet11!A:B,2,false) -> Cyprus | E24: 18.333333 | F24: 19400.358
A25: CZE | B25: 20.666667 | D25: =VLOOKUP(A25,Sheet11!A:B,2,false) -> Czechia | E25: 20.666667
A26: DEU | B26: 10.256762 | C26: 43393.776 | D26: =VLOOKUP(A26,Sheet11!A:B,2,false) -> Germany | E26: 10.256762 | F26: 43393.776
A27: DNK | B27: 19 | C27: 56635.387 | D27: =VLOOKUP(A27,Sheet11!A:B,2,false) -> Denmark | E27: 19 | F27: 56635.387
A28: ESP | B28: 1.046125 | C28: 27193.029 | D28: =VLOOKUP(A28,Sheet11!A:B,2,false) -> Spain | E28: 1.046125 | F28: 27193.029
A29: EST | B29: 21.666667 | C29: 19628.299 | D29: =VLOOKUP(A29,Sheet11!A:B,2,false) -> Estonia | E29: 21.666667 | F29: 19628.299
A30: ETH | B30: 25.566667 | C30: 728.83752 | D30: =VLOOKUP(A30,Sheet11!A:B,2,false) -> Ethiopia | E30: 25.566667 | F30: 728.83752
A31: FIN | B31: 17.666667 | C31: 44709.162 | D31: =VLOOKUP(A31,Sheet11!A:B,2,false) -> Finland | E31: 17.666667 | F31: 44709.162
A32: FJI | B32: 6.275 | C32: 5303.4892 | D32: =VLOOKUP(A32,Sheet11!A:B,2,false) -> Fiji | E32: 6.275 | F32: 5303.4892
A33: FRA | B33: 20.05 | C33: 37820.619 | D33: =VLOOKUP(A33,Sheet11!A:B,2,false) -> France | E33: 20.05 | F33: 37820.619
A34: GBR | B34: 20.142857 | C34: 46542.497 | D34: =VLOOKUP(A34,Sheet11!A:B,2,false) -> United Kingdom of Great Britain and Northern Ireland (the) | E34: 20.142857 | F34: 46542.497
A35: GEO | B35: 1.6375 | C35: 4996.7131 | D35: =VLOOKUP(A35,Sheet11!A:B,2,false) -> Georgia | E35: 1.6375 | F35: 4996.7131
A36: GHA | B36: 24.533333 | C36: 1933.9453 | D36: =VLOOKUP(A36,Sheet11!A:B,2,false) -> Ghana | E36: 24.533333 | F36: 1933.9453
A37: GIN | B37: 10.4 | C37: 905.14782 | D37: =VLOOKUP(A37,Sheet11!A:B,2,false) -> Guinea | E37: 10.4 | F37: 905.14782
... A96: UGA | B96: 35.7 | C96: 907.45786 | D96: =VLOOKUP(A96,Sheet11!A:B,2,false) -> Uganda | E96: 35.7 | F96: 907.45786
A97: VNM | B97: 0.8625 | D97: =VLOOKUP(A97,Sheet11!A:B,2,false) -> Viet Nam | E97: 0.8625
A98: VUT | B98: 11.753124 | C98: 2823.133 | D98: =VLOOKUP(A98,Sheet11!A:B,2,false) -> Vanuatu | E98: 11.753124 | F98: 2823.133
A99: WSM | B99: 6.4875 | C99: 4325.8784 | D99: =VLOOKUP(A99,Sheet11!A:B,2,false) -> Samoa | E99: 6.4875 | F99: 4325.8784
A100: ZAF | B100: 1.5214286 | C100: 5928.8865 | D100: =VLOOKUP(A100,Sheet11!A:B,2,false) -> South Africa | E100: 1.5214286 | F100: 5928.8865
A101: ZMB | B101: 30.633333 | C101: 1300.0551 | D101: =VLOOKUP(A101,Sheet11!A:B,2,false) -> Zambia | E101: 30.633333 | F101: 1300.0551
A102: ZWE | B102: 6.55 | C102: 1377.0661 | D102: =VLOOKUP(A102,Sheet11!A:B,2,false) -> Zimbabwe | E102: 6.55 | F102: 1377.0661

Sheet Sheet13
A1: developing | B1: Current Well-being | C1: Equity & Inclusion | D1: Foundational Principles | E1: Sustainability & Resilience
A2: Developed | B2: 0.66386555 | C2: 0.64052288 | D2: 0.71764706 | E2: 0.56944444
A3: Developing | B3: 0.45875252 | C3: 0.59859155 | D3: 0.56 | E3: 0.32474227
A9: developing | B9: Current Well-being | C9: Equity & Inclusion | D9: Foundational Principles | E9: Sustainability & Resilience
A10: Developed | B10: 0.13857143 | C10: 0.2 | D10: 0.078571429 | E10: 0.2
A11: Developing | B11: 0.17 | C11: 0.16666667 | D11: 0.18773946 | E11: 0.16666667
A14: developing | B14: group | C14: proportion
A15: developed | B15: Current Well-being
A16: developed | B16: Equity & Inclusion
A17: developed | B17: Foundational Principles
A18: developed | B18: Sustainability & Resilience
A19: developing | B19: Current Well-being
A20: developing | B20: Equity & Inclusion
A21: developing | B21: Foundational Principles
A22: developing | B22: Sustainability & Resilience

Sheet Sheet11
A1: Alpha-3 code | B1: Country | C1: Alpha-2 code | D1: Alpha-3 code | E1: Numeric
A2: AFG | B2: Afghanistan | C2: AF | D2: AFG | E2: 4
A3: ALB | B3: Albania | C3: AL | D3: ALB | E3: 8
A4: DZA | B4: Algeria | C4: DZ | D4: DZA | E4: 12
A5: ASM | B5: American Samoa | C5: AS | D5: ASM | E5: 16
A6: AND | B6: Andorra | C6: AD | D6: AND | E6: 20
A7: AGO | B7: Angola | C7: AO | D7: AGO | E7: 24
A8: AIA | B8: Anguilla | C8: AI | D8: AIA | E8: 660
A9: ATA | B9: Antarctica | C9: AQ | D9: ATA | E9: 10
A10: ATG | B10: Antigua and Barbuda | C10: AG | D10: ATG | E10: 28
A11: ARG | B11: Argentina | C11: AR | D11: ARG | E11: 32
A12: ARM | B12: Armenia | C12: AM | D12: ARM | E12: 51
A13: ABW | B13: Aruba | C13: AW | D13: ABW | E13: 533
... A250: ALA | B250: Åland Islands | C250: AX | D250: ALA | E250: 248
